Workbook

Sheet Instrucciones
B2: Plantilla estandarizada de órdenes de compra (OC) y de servicio (OS) · ÖRÖK
B3: Versión 1 · 28/10/2026. Sirve hasta que el módulo de Logística del ERP genere las órdenes; tiene los mismos campos que el PDF del ERP.
B5: Cómo emitir una orden
B6: 1. Haz una copia de la hoja de la empresa y el tipo que corresponda (por ejemplo «OC BMG») y nómbrala con el número de la orden.
B7: 2. Completa solo las celdas amarillas. Las demás se llenan solas desde «Empresas» y «Proveedores».
B8: 3. El número se arma con la empresa, el año de la fecha y el correlativo: OC-BMG-2026-0041. Usa el correlativo que indica «Empresas» en la columna Siguiente.
B9: 4. Elige el proveedor de la lista. Si es nuevo, regístralo primero en «Proveedores» con su RUC y su cuenta de abono.
B10: 5. Imprime en A4 (ya está configurado) o exporta a PDF. Las firmas van en los cuatro recuadros del pie: a mano, o con firma digital sobre el PDF.
B11: 6. Anota la orden en «Registro» para que el correlativo y los totales queden al día.
B13: Reglas de cálculo
B14: IGV 18 %: solo cuando el comprobante es factura electrónica. Recibo por honorarios, boleta y pagos sin comprobante (tasas, tributos) no suman IGV.
B15: Retención de 4.ª categoría 8 %: en recibos por honorarios mayores a S/ 1,500. Confirma el tope vigente con Contabilidad.
... B22: Leyenda: las celdas amarillas son las únicas que se editan. Las hojas de ejemplo traen datos reales de órdenes anteriores para mostrar el formato esperado.

Sheet Empresas
A1: Código | B1: Razón social | C1: RUC | D1: Dirección fiscal | E1: Teléfono | F1: Correo de compras | G1: Web | H1: Siguiente OC | I1: Siguiente OS
A2: BMG | B2: BMG DESARROLLADORA INMOBILIARIA S.A.C. | C2: 20615227685 | D2: Calle Puquina 138, Maranga, San Miguel, Lima | E2: Cel. 987 208 622 | F2: compras@orok.com.pe | G2: www.orok.com.pe | H2: =SUMPRODUCT(MAX((Registro!$A$6:$A$400=$A2)*(Registro!$B$6:$B$400="OC")*Registro!$C$6:$C$400))+1 -> 41 | I2: =SUMPRODUCT(MAX((Registro!$A$6:$A$400=$A2)*(Registro!$B$6:$B$400="OS")*Registro!$C$6:$C$400))+1 -> 47
A3: MZA | B3: MONTEZUMA ARQUITECTOS GERENCIA Y CONSTRUCCIÓN E.I.R.L. | C3: 20602354785 | D3: Calle Puquina 138, Maranga, San Miguel, Lima | E3: Cel. 940 207 936 | F3: info@montezumaarquitectos.com | G3: www.montezumaarquitectos.com | H3: =SUMPRODUCT(MAX((Registro!$A$6:$A$400=$A3)*(Registro!$B$6:$B$400="OC")*Registro!$C$6:$C$400))+1 -> 32 | I3: =SUMPRODUCT(MAX((Registro!$A$6:$A$400=$A3)*(Registro!$B$6:$B$400="OS")*Registro!$C$6:$C$400))+1 -> 1
A4: EMP3 | B4: Tercera empresa (por definir) | H4: =SUMPRODUCT(MAX((Registro!$A$6:$A$400=$A4)*(Registro!$B$6:$B$400="OC")*Registro!$C$6:$C$400))+1 -> 1 | I4: =SUMPRODUCT(MAX((Registro!$A$6:$A$400=$A4)*(Registro!$B$6:$B$400="OS")*Registro!$C$6:$C$400))+1 -> 1

Sheet Proveedores
A1: Catálogo de proveedores · completar RUC y cuenta de abono antes de emitir
A2: Nombres tomados de las órdenes anteriores (OCOS_OROK_.xlsx). Las celdas amarillas están por completar.
A4: Proveedor | B4: RUC / DNI | C4: Comprobante habitual | D4: Dirección | E4: Contacto | F4: Teléfono | G4: Correo | H4: Banco | I4: Moneda | J4: N.º de cuenta | K4: CCI
A5: ARES
A6: ARTESA
A7: BLUEDRAGON CORPORATION SAC
A8: CCD EDUCA EIRL
A9: CREALAB
A10: DEVERCOMP | F10: 921 295 210
A11: DIEGO ESPINOZA
A12: FERNANDO CASTILLO
A13: GRAPHCOLOR
A14: GUILLERMO BUSTAMANTE
A15: IKASA
A16: IMPORT HNOS SAN LUIS SAC | F16: 977 208 514
A17: JORGE ORESTES CUSTODIO GUTIERREZ
A18: KUBIKO
A19: LAYSECA ASOCIADOS SAC | B19: 20523123611 | I19: Soles | J19: 053-001-001251053001-42
A20: MARTINEZ RAMOS IRINA MERCEDEZ
A21: MAYO MATERIALES E INSTALACIONES
A22: META PLATFORMS (PUBLICIDAD) | C22: Factura del exterior
A23: MIFIBRA
A24: MINERA LUREN | E24: Mónica Demitriades | H24: BCP | I24: Soles | J24: 193-1544231-0-92 | K24: 002-193-001544231092-14
A25: MUNICIPALIDAD DE SAN MIGUEL | C25: Sin comprobante (tasas, tributos)
A26: NEOPATISH
A27: PORTCARRERO ALARCON ISAAC
A28: REVEP PAREDES Y TEXTURAS
A29: SAMAY DIST INDUSTRIAL EIRL
A30: SLINKY
A31: SMART LOCKS PERU
A32: SMS CONSULTING AND TRAINING SAC
A33: SODIMAC
A34: TUNOPAL S.A. | D34: Av. Camino Real 1125, Urb. Fundo Conde de San Isidro, Lima | F34: 999 988 850 | H34: BCP | I34: Soles | J34: 1932525695069
A35: VALOREM Y CONSULTORES

Sheet Registro
A1: Registro de órdenes de compra y de servicio
A2: Importado de OCOS_OROK_.xlsx (64 hojas de orden) el 28/10/2026. Montos tal como figuran en cada hoja; la columna Revisar marca lo que no cuadra.
A5: Empresa | B5: Tipo | C5: Correlativo | D5: N.º estándar | E5: N.º original | F5: Hoja | G5: Fecha | H5: Proyecto | I5: Proveedor | J5: Subtotal | K5: IGV | L5: Total | M5: Recalculado (cant × p.u.) | N5: Revisar | P5: Resumen
A6: BMG | B6: OC | C6: 20 | D6: OC-BMG-2026-0020 | E6: 0020-PROYINFINITY224-SHOWROOM | F6: 0020 OC ARES | G6: 46148 | H6: INFINITY224 | I6: ARES | J6: 565.64 | K6: 101.82 | L6: 667.46 | M6: 565.64 | P6: Empresa | Q6: Tipo | R6: Órdenes | S6: Subtotal | T6: IGV | U6: Total | V6: Por revisar
A7: BMG | B7: OC | C7: 21 | D7: OC-BMG-2026-0021 | E7: 0021-PROYINFINITY224-SHOWROOM | F7: 0021 OC Revep | G7: 46148 | H7: INFINITY224 | I7: REVEP paredes y texturas | J7: 358.47 | K7: 64.52 | L7: 422.99 | M7: 358.47 | P7: BMG | Q7: OC | R7: =COUNTIFS($A$6:$A$69,P7,$B$6:$B$69,Q7) -> 21 | S7: =SUMIFS($J$6:$J$69,$A$6:$A$69,P7,$B$6:$B$69,Q7) -> 8006.34 | T7: =SUMIFS($K$6:$K$69,$A$6:$A$69,P7,$B$6:$B$69,Q7) -> 1396.77 | U7: =SUMIFS($L$6:$L$69,$A$6:$A$69,P7,$B$6:$B$69,Q7) -> 9403.11 | V7: =COUNTIFS($A$6:$A$69,P7,$B$6:$B$69,Q7,$N$6:$N$69,"?*") -> 6
A8: BMG | B8: OC | C8: 22 | D8: OC-BMG-2026-0022 | E8: 0022-PROYINFINITY224-SHOWROOM | F8: 0022 OC Samay | G8: 46148 | H8: INFINITY224 | I8: SAMAY DIST INDUSTRIAL EIRL | J8: 177.12 | K8: 31.88 | L8: 209 | M8: 177.12 | P8: BMG | Q8: OS | R8: =COUNTIFS($A$6:$A$69,P8,$B$6:$B$69,Q8) -> 37 | S8: =SUMIFS($J$6:$J$69,$A$6:$A$69,P8,$B$6:$B$69,Q8) -> 46305.37 | T8: =SUMIFS($K$6:$K$69,$A$6:$A$69,P8,$B$6:$B$69,Q8) -> 7830.45 | U8: =SUMIFS($L$6:$L$69,$A$6:$A$69,P8,$B$6:$B$69,Q8) -> 54135.82 | V8: =COUNTIFS($A$6:$A$69,P8,$B$6:$B$69,Q8,$N$6:$N$69,"?*") -> 5
A9: BMG | B9: OC | C9: 23 | D9: OC-BMG-2026-0023 | E9: 0023-PROYINFINITY224-SHOWROOM | F9: 0023 OC Mayo | G9: 46148 | H9: INFINITY224 | I9: Mayo Materiales e Instalaciones | J9: 93.29 | K9: 16.79 | L9: 110.08 | M9: 93.29 | P9: MZA | Q9: OC | R9: =COUNTIFS($A$6:$A$69,P9,$B$6:$B$69,Q9) -> 6 | S9: =SUMIFS($J$6:$J$69,$A$6:$A$69,P9,$B$6:$B$69,Q9) -> 28158 | T9: =SUMIFS($K$6:$K$69,$A$6:$A$69,P9,$B$6:$B$69,Q9) -> 5068.44 | U9: =SUMIFS($L$6:$L$69,$A$6:$A$69,P9,$B$6:$B$69,Q9) -> 33226.44 | V9: =COUNTIFS($A$6:$A$69,P9,$B$6:$B$69,Q9,$N$6:$N$69,"?*") -> 2
A10: BMG | B10: OC | C10: 24 | D10: OC-BMG-2026-0024 | E10: 0024-PROYINFINITY224-SHOWROOM | F10: 0024 OC Mayo | G10: 46148 | H10: INFINITY224 | I10: Mayo Materiales e Instalaciones | J10: 643.22 | K10: 115.78 | L10: 759 | M10: 527.9 | N10: Subtotal 643.22 no coincide con cant × p.u. 527.90 | P10: MZA | Q10: OS | R10: =COUNTIFS($A$6:$A$69,P10,$B$6:$B$69,Q10) -> 0 | S10: =SUMIFS($J$6:$J$69,$A$6:$A$69,P10,$B$6:$B$69,Q10) -> 0 | T10: =SUMIFS($K$6:$K$69,$A$6:$A$69,P10,$B$6:$B$69,Q10) -> 0 | U10: =SUMIFS($L$6:$L$69,$A$6:$A$69,P10,$B$6:$B$69,Q10) -> 0 | V10: =COUNTIFS($A$6:$A$69,P10,$B$6:$B$69,Q10,$N$6:$N$69,"?*") -> 0
A11: BMG | B11: OC | C11: 25 | D11: OC-BMG-2026-0025 | E11: 0025-PROYINFINITY224-SHOWROOM | F11: 0025 OC SmartLocks | G11: 46148 | H11: INFINITY224 | I11: Smart Locks Peru | J11: 634.74 | K11: 114.25 | L11: 748.99 | M11: 634.74 | P11: Total | R11: =SUM(R7:R10) -> 64 | S11: =SUM(S7:S10) -> 82469.71 | T11: =SUM(T7:T10) -> 14295.66 | U11: =SUM(U7:U10) -> 96765.37 | V11: =SUM(V7:V10) -> 13
A12: BMG | B12: OC | C12: 26 | D12: OC-BMG-2026-0026 | E12: 0026-PROYINFINITY224-SHOWROOM | F12: 0026 OC Ikasa | G12: 46150 | H12: INFINITY224 | I12: IKASA | J12: 343.2 | K12: 61.78 | L12: 404.98 | M12: 343.2
A13: BMG | B13: OC | C13: 27 | D13: OC-BMG-2026-0027 | E13: 0027-PROYINFINITY224-SHOWROOM | F13: 0027 OC WallPanel | G13: 46150 | H13: INFINITY224 | I13: Kubiko | J13: 506.95 | K13: 91.25 | L13: 598.2 | M13: 506.95 | P13: Montos sin distinguir moneda: las hojas originales no indican si están en soles o dólares.
A14: BMG | B14: OC | C14: 28 | D14: OC-BMG-2026-0028 | E14: 0028-PROYINFINITY224-SHOWROOM | F14: 0028 OC Varias Compras | G14: 46150 | H14: INFINITY224 | I14: — | J14: 246.48 | K14: 0 | L14: 246.48 | M14: 246.48
A15: BMG | B15: OC | C15: 29 | D15: OC-BMG-2026-0029 | E15: 0029-PROYINFINITY224-SHOWROOM | F15: 0029OC Impor Export Grupo | G15: 46156 | H15: INFINITY224 | I15: — | J15: 269.5 | K15: 48.51 | L15: 318.01 | M15: 269.5 | N15: Número repetido
A16: BMG | B16: OC | C16: 29 | D16: OC-BMG-2026-0029 | E16: 0029-PROYINFINITY224-SHOWROOM | F16: 0033OC Banner exterior | G16: 46169 | H16: INFINITY224 | I16: Guillermo Bustamante | J16: 338.98 | K16: 61.02 | L16: 400 | M16: 338.98 | N16: Número repetido · La hoja dice 0033 y la orden 0029 · Proveedor persona: revisar si es recibo por honorarios (sin IGV)
A17: BMG | B17: OC | C17: 30 | D17: OC-BMG-2026-0030 | E17: 0030-PROYINFINITY224-SHOWROOM | F17: 0030OC Asturias | G17: 46162 | H17: INFINITY224 | I17: Diego Espinoza | J17: 727.79 | K17: 131 | L17: 858.79 | M17: 727.79 | N17: Proveedor persona: revisar si es recibo por honorarios (sin IGV)
A18: BMG | B18: OC | C18: 31 | D18: OC-BMG-2026-0031 | E18: 0031-PROYINFINITY224-SHOWROOM | F18: 0031 OCcompras varias | G18: 46148 | H18: INFINITY224 | I18: compras varias | J18: 958.15 | K18: 172.47 | L18: 1130.62 | M18: 958.15 | N18: Posible IGV duplicado: las líneas citan comprobantes ya emitidos
A19: BMG | B19: OC | C19: 32 | D19: OC-BMG-2026-0032 | E19: 0032-PROYINFINITY224-SHOWROOM | F19: 0032 OC Papeleria | G19: 46179 | H19: INFINITY224 | I19: Papeleria | J19: 272.03 | K19: 48.97 | L19: 321 | M19: 272.03
A20: BMG | B20: OC | C20: 34 | D20: OC-BMG-2026-0034 | E20: 0034-PROYINFINITY224-SHOWROOM | F20: 0034 OC MOBEL | G20: 46189 | H20: INFINITY224 | I20: PORTCARRERO ALARCON ISAAC | J20: 207.63 | K20: 37.37 | L20: 245 | M20: 207.63 | N20: Proveedor persona: revisar si es recibo por honorarios (sin IGV)
A21: BMG | B21: OC | C21: 35 | D21: OC-BMG-2026-0035 | E21: 0035-PROYINFINITY224-SHOWROOM | F21: 0035 OC ARTESA | G21: 46189 | H21: INFINITY224 | I21: ARTESA | J21: 266.95 | K21: 48.05 | L21: 315 | M21: 266.95
A22: BMG | B22: OC | C22: 36 | D22: OC-BMG-2026-0036 | E22: 0036-PROYINFINITY224-SHOWROOM | F22: 0036 DEVERCOMP | G22: 46189 | H22: INFINITY224 | I22: DEVERCOMP | J22: 31.69 | K22: 5.7 | L22: 37.39 | M22: 31.69
A23: BMG | B23: OC | C23: 37 | D23: OC-BMG-2026-0037 | E23: 0037-PROYINFINITY224-SHOWROOM | F23: 0037 BLUEDRAGON | G23: 46189 | H23: INFINITY224 | I23: BLUEDRAGON CORPORATION SAC | J23: 40.32 | K23: 7.26 | L23: 47.58 | M23: 40.32
A24: BMG | B24: OC | C24: 38 | D24: OC-BMG-2026-0038 | E24: 0038-PROYINFINITY224-SHOWROOM | F24: 0038 OCcompras varias | G24: 46201 | H24: INFINITY224 | I24: compras varias | J24: 803 | K24: 144.54 | L24: 947.54 | M24: 803
A25: BMG | B25: OC | C25: 39 | D25: OC-BMG-2026-0039 | E25: 0039-PROYINFINITY224-SHOWROOM | F25: 0039 DEVERCOMP | G25: 46189 | H25: INFINITY224 | I25: DEVERCOMP | J25: 500.85 | K25: 90.15 | L25: 591 | M25: 500.85
A26: BMG | B26: OC | C26: 40 | D26: OC-BMG-2026-0040 | E26: 0040-PROYINFINITY224-SHOWROOM | F26: 0040 Soporte Vidrio | G26: 46181 | H26: INFINITY224 | I26: IMPORT HNOS SAN LUIS SAC | J26: 20.34 | K26: 3.66 | L26: 24 | M26: 20.34
A27: BMG | B27: OS | C27: 10 | D27: OS-BMG-2025-0010 | E27: 0010-PROYINFINITY224-SHOWROOM | F27: 0010 OS Crealab | G27: 45844 | H27: INFINITY224 | I27: Crealab | J27: 4250 | K27: 765 | L27: 5015 | M27: 4250
A28: BMG | B28: OS | C28: 11 | D28: OS-BMG-2025-0011 | E28: 0011-PROYINFINITY224-SHOWROOM | F28: 0011 OS Crealab | G28: 45875 | H28: INFINITY224 | I28: Crealab | J28: 1300 | K28: 234 | L28: 1534 | M28: 1300
A29: BMG | B29: OS | C29: 12 | D29: OS-BMG-2025-0012 | E29: 0012-PROYINFINITY224-SHOWROOM | F29: 0012 OS Crealab | G29: 45906 | H29: INFINITY224 | I29: Crealab | J29: 1300 | K29: 234 | L29: 1534 | M29: 1300
A30: BMG | B30: OS | C30: 13 | D30: OS-BMG-2025-0013 | E30: 0013-PROYINFINITY224-SHOWROOM | F30: 0013 OS Crealab | G30: 45936 | H30: INFINITY224 | I30: Crealab | J30: 1300 | K30: 234 | L30: 1534 | M30: 1300
A31: BMG | B31: OS | C31: 14 | D31: OS-BMG-2025-0014 | E31: 0014-PROYINFINITY224-SHOWROOM | F31: 0014 OS Crealab | G31: 45967 | H31: INFINITY224 | I31: Crealab | J31: 1300 | K31: 234 | L31: 1534 | M31: 1300
A32: BMG | B32: OS | C32: 15 | D32: OS-BMG-2025-0015 | E32: 0015-PROYINFINITY224-SHOWROOM | F32: 0015 OS Crealab | G32: 45997 | H32: INFINITY224 | I32: Crealab | J32: 1300 | K32: 234 | L32: 1534 | M32: 1300
... A43: BMG | B43: OS | C43: 26 | D43: OS-BMG-2026-0026 | E43: 0026-PROYINFINITY224-SHOWROOM | F43: 0026 OS Tramites | G43: 46156 | H43: INFINITY224 | I43: Fernando Castillo | J43: 926 | K43: 0 | L43: 926 | M43: 926
A44: BMG | B44: OS | C44: 27 | D44: OS-BMG-2026-0027 | E44: 0027-PROYINFINITY224-SHOWROOM | F44: 0027OS Isotipo | G44: 46156 | H44: INFINITY224 | I44: Jorge Orestes Custodio Gutierrez | J44: 950 | K44: 171 | L44: 1121 | M44: 950 | N44: Proveedor persona: revisar si es recibo por honorarios (sin IGV)
A45: BMG | B45: OS | C45: 28 | D45: OS-BMG-2026-0028 | E45: 0028-PROYINFINITY224-SHOWROOM | F45: 0028OS Doble99 | G45: 46113 | H45: INFINITY224 | I45: Guillermo Bustamante | J45: 3500 | K45: 630 | L45: 4130 | M45: 3500 | N45: Proveedor persona: revisar si es recibo por honorarios (sin IGV)
A46: BMG | B46: OS | C46: 30 | D46: OS-BMG-2026-0030 | E46: 0030-PROYINFINITY224-SHOWROOM | F46: 0030 OS TUNA | G46: 46178 | H46: INFINITY224 | I46: TUNOPAL S.A. | J46: 473.14 | K46: 85.17 | L46: 558.31 | M46: 473.14
A47: BMG | B47: OS | C47: 31 | D47: OS-BMG-2026-0031 | E47: 0031-PROYINFINITY224-SHOWROOM | F47: 0031 OS TUNA | G47: 46179 | H47: INFINITY224 | I47: TUNOPAL S.A. | J47: 50 | K47: 9 | L47: 59 | M47: 50
A48: BMG | B48: OS | C48: 32 | D48: OS-BMG-2026-0032 | E48: 0032-PROYINFINITY224-SHOWROOM | F48: 0032 OS TUNA | G48: 46198 | H48: INFINITY224 | I48: TUNOPAL S.A. | J48: 4500 | K48: 810 | L48: 5310 | M48: 4500
A49: BMG | B49: OS | C49: 33 | D49: OS-BMG-2026-0033 | E49: 0033-PROYINFINITY224-SHOWROOM | F49: 0033 OS TUNA | G49: 46206 | H49: INFINITY224 | I49: TUNOPAL S.A. | J49: 50 | K49: 9 | L49: 59 | M49: 50
A50: BMG | B50: OS | C50: 34 | D50: OS-BMG-2026-0034 | E50: 0034-PROYINFINITY224-SHOWROOM | F50: 0034 OS TUNA | G50: 46206 | H50: INFINITY224 | I50: TUNOPAL S.A. | J50: 1253.28 | K50: 225.59 | L50: 1478.87 | M50: 1253.28
A51: BMG | B51: OS | C51: 35 | D51: OS-BMG-2026-0035 | E51: 0035-PROYINFINITY224-SHOWROOM | F51: 0035 OS Mifibra | G51: 46199 | H51: INFINITY224 | I51: mifibra | J51: 27.03 | K51: 4.87 | L51: 31.9 | M51: 27.03
A52: BMG | B52: OS | C52: 36 | D52: OS-BMG-2026-0036 | E52: 0036-PROYINFINITY224-SHOWROOM | F52: 0036 OS Encuadernado | G52: 46196 | H52: INFINITY224 | I52: Martinez ramos irina mercedez | J52: 120 | K52: 21.6 | L52: 141.6 | M52: 120 | N52: Proveedor persona: revisar si es recibo por honorarios (sin IGV)
...

Sheet OC BMG
E1: ORDEN DE COMPRA
E2: Empresa | F2: Código | G2: BMG
E3: Correlativo | G3: 39
E4: Fecha | G4: 46189
A5: =INDEX(Empresas!$A$2:$G$4,MATCH($G$2,Empresas!$A$2:$A$4,0),2) -> BMG DESARROLLADORA INMOBILIARIA S.A.C. | E5: N.º | F5: ="OC-"&$G$2&"-"&IF($G$4="","AAAA",YEAR($G$4))&"-"&TEXT($G$3,"0000") -> OC-BMG-2026-0039
A6: ="RUC "&INDEX(Empresas!$A$2:$G$4,MATCH($G$2,Empresas!$A$2:$A$4,0),3)&" · "&INDEX(Empresas!$A$2:$G$4,MATCH($G$2,Empresas!$A$2:$A$4,0),4) -> RUC 20615227685 · Calle Puquina 138, Maranga, San Miguel, Lima | E6: Revisión | G6: 0
A7: =INDEX(Empresas!$A$2:$G$4,MATCH($G$2,Empresas!$A$2:$A$4,0),5)&" · "&INDEX(Empresas!$A$2:$G$4,MATCH($G$2,Empresas!$A$2:$A$4,0),6)&" · "&INDEX(Empresas!$A$2:$G$4,MATCH($G$2,Empresas!$A$2:$A$4,0),7) -> Cel. 987 208 622 · compras@orok.com.pe · www.orok.com.pe
B9: PROVEEDOR | E9: FACTURAR A
B10: Proveedor | C10: DEVERCOMP | E10: Razón social | F10: =INDEX(Empresas!$A$2:$G$4,MATCH($G$2,Empresas!$A$2:$A$4,0),2) -> BMG DESARROLLADORA INMOBILIARIA S.A.C.
B11: RUC / DNI | C11: =IFERROR(INDEX(Proveedores!$A$5:$K$65,MATCH($C$10,Proveedores!$A$5:$A$65,0),2)&"","") | E11: RUC | F11: =INDEX(Empresas!$A$2:$G$4,MATCH($G$2,Empresas!$A$2:$A$4,0),3) -> 20615227685
B12: Dirección | C12: =IFERROR(INDEX(Proveedores!$A$5:$K$65,MATCH($C$10,Proveedores!$A$5:$A$65,0),4)&"","") | E12: Dir. fiscal | F12: =INDEX(Empresas!$A$2:$G$4,MATCH($G$2,Empresas!$A$2:$A$4,0),4) -> Calle Puquina 138, Maranga, San Miguel, Lima
B13: Contacto | C13: =TRIM(IFERROR(INDEX(Proveedores!$A$5:$K$65,MATCH($C$10,Proveedores!$A$5:$A$65,0),5)&"","")&" "&IFERROR(INDEX(Proveedores!$A$5:$K$65,MATCH($C$10,Proveedores!$A$5:$A$65,0),6)&"","")) -> 921 295 210 | E13: Comprobante | F13: Factura electrónica
B14: Cotización | E14: Moneda | F14: PEN
B16: PROYECTO | E16: ENTREGA
B17: Proyecto | C17: INFINITY 224 | E17: Lugar | F17: Showroom Infinity 224
B18: Centro de costo | C18: Showroom | E18: Dirección | F18: Calle La Apacheta 224, San Miguel, Lima
B19: Partida | C19: Equipamiento del showroom | E19: Contacto | F19: Martín Montezuma · 987 208 622
B20: Requerimiento | E20: Horario / plazo | F20: L-V 9:30–12:00 y 14:00–16:00 · S 9:30–12:00
A22: # | B22: Código | C22: Descripción | D22: Und. | E22: Cantidad | F22: P. unitario | G22: Parcial
A23: 1 | C23: Impresora multifuncional Brother DCP-T430W, Wi-Fi · serie U67684A6H980457 | D23: und | E23: 1 | F23: 500.85 | G23: =IF(OR(E23="",F23=""),"",ROUND(E23*F23,2)) -> 500.85
A24: 2 | G24: =IF(OR(E24="",F24=""),"",ROUND(E24*F24,2))
A25: 3 | G25: =IF(OR(E25="",F25=""),"",ROUND(E25*F25,2))
A26: 4 | G26: =IF(OR(E26="",F26=""),"",ROUND(E26*F26,2))
A27: 5 | G27: =IF(OR(E27="",F27=""),"",ROUND(E27*F27,2))
A28: 6 | G28: =IF(OR(E28="",F28=""),"",ROUND(E28*F28,2))
A29: 7 | G29: =IF(OR(E29="",F29=""),"",ROUND(E29*F29,2))
A30: 8 | G30: =IF(OR(E30="",F30=""),"",ROUND(E30*F30,2))
A31: 9 | G31: =IF(OR(E31="",F31=""),"",ROUND(E31*F31,2))
A32: 10 | G32: =IF(OR(E32="",F32=""),"",ROUND(E32*F32,2))
A33: 11 | G33: =IF(OR(E33="",F33=""),"",ROUND(E33*F33,2))
A34: 12 | G34: =IF(OR(E34="",F34=""),"",ROUND(E34*F34,2))
B36: CONDICIONES
B37: Forma de pago | C37: Contado, contra entrega y factura | E37: Subtotal | G37: =ROUND(SUM(G23:G34),2) -> 500.85
B38: Plazo | C38: Entrega en 3 días hábiles | E38: IGV 18 % | G38: =IF(F13="Factura electrónica",ROUND(G37*0.18,2),0) -> 90.15
B39: Garantía | C39: Garantía del fabricante | E39: Otros cargos | G39: 0
B40: Penalidad | E40: Total | G40: =ROUND(G37+G38+G39,2) -> 591
B41: Abonar en | C41: =IF(IFERROR(INDEX(Proveedores!$A$5:$K$65,MATCH($C$10,Proveedores!$A$5:$A$65,0),10)&"","")="","Cuenta del proveedor por registrar en Proveedores",TRIM(IFERROR(INDEX(Proveedores!$A$5:$K$65,MATCH($C$10,Proveedores!$A$5:$A$65,0),8)&"","")&" "&IFERROR(INDEX(Proveedores!$A$5:$K$65,MATCH($C$10,Proveedores!$A$5:$A$65,0),9)&"","")&" · "&IFERROR(INDEX(Proveedores!$A$5:$K$65,MATCH($C$10,Proveedores!$A$5:$A$65,0),10)&"","")&IF(IFERROR(INDEX(Proveedores!$A$5:$K$65,MATCH($C$10,Proveedores!$A$5:$A$65,0),11)&"","")="",""," · CCI "&IFERROR(INDEX(Proveedores!$A$5:$K$65,MATCH($C$10,Proveedores!$A$5:$A$65,0),11)&"","")))) -> Cuenta del proveedor por registrar en Proveedores | E41: Detracción % | G41: =IF(F41="",0,ROUND(G40*F41,0)) -> 0
E42: Retención 4.ª cat. | G42: =IF(AND(F13="Recibo por honorarios",G37>1500),ROUND(G37*0.08,2),0) -> 0
E43: Neto a pagar | G43: =G40-G41-G42 -> 591
B44: OBSERVACIONES | E44: =IF($F$14="USD","Montos en dólares americanos","Montos en soles") -> Montos en soles
...

Sheet OS BMG
E1: ORDEN DE SERVICIO
E2: Empresa | F2: Código | G2: BMG
E3: Correlativo | G3: 45
E4: Fecha | G4: 46235
A5: =INDEX(Empresas!$A$2:$G$4,MATCH($G$2,Empresas!$A$2:$A$4,0),2) -> BMG DESARROLLADORA INMOBILIARIA S.A.C. | E5: N.º | F5: ="OS-"&$G$2&"-"&IF($G$4="","AAAA",YEAR($G$4))&"-"&TEXT($G$3,"0000") -> OS-BMG-2026-0045
A6: ="RUC "&INDEX(Empresas!$A$2:$G$4,MATCH($G$2,Empresas!$A$2:$A$4,0),3)&" · "&INDEX(Empresas!$A$2:$G$4,MATCH($G$2,Empresas!$A$2:$A$4,0),4) -> RUC 20615227685 · Calle Puquina 138, Maranga, San Miguel, Lima | E6: Revisión | G6: 0
A7: =INDEX(Empresas!$A$2:$G$4,MATCH($G$2,Empresas!$A$2:$A$4,0),5)&" · "&INDEX(Empresas!$A$2:$G$4,MATCH($G$2,Empresas!$A$2:$A$4,0),6)&" · "&INDEX(Empresas!$A$2:$G$4,MATCH($G$2,Empresas!$A$2:$A$4,0),7) -> Cel. 987 208 622 · compras@orok.com.pe · www.orok.com.pe
B9: PROVEEDOR | E9: FACTURAR A
B10: Proveedor | C10: TUNOPAL S.A. | E10: Razón social | F10: =INDEX(Empresas!$A$2:$G$4,MATCH($G$2,Empresas!$A$2:$A$4,0),2) -> BMG DESARROLLADORA INMOBILIARIA S.A.C.
B11: RUC / DNI | C11: =IFERROR(INDEX(Proveedores!$A$5:$K$65,MATCH($C$10,Proveedores!$A$5:$A$65,0),2)&"","") | E11: RUC | F11: =INDEX(Empresas!$A$2:$G$4,MATCH($G$2,Empresas!$A$2:$A$4,0),3) -> 20615227685
B12: Dirección | C12: =IFERROR(INDEX(Proveedores!$A$5:$K$65,MATCH($C$10,Proveedores!$A$5:$A$65,0),4)&"","") -> Av. Camino Real 1125, Urb. Fundo Conde de San Isidro, Lima | E12: Dir. fiscal | F12: =INDEX(Empresas!$A$2:$G$4,MATCH($G$2,Empresas!$A$2:$A$4,0),4) -> Calle Puquina 138, Maranga, San Miguel, Lima
B13: Contacto | C13: =TRIM(IFERROR(INDEX(Proveedores!$A$5:$K$65,MATCH($C$10,Proveedores!$A$5:$A$65,0),5)&"","")&" "&IFERROR(INDEX(Proveedores!$A$5:$K$65,MATCH($C$10,Proveedores!$A$5:$A$65,0),6)&"","")) -> 999 988 850 | E13: Comprobante | F13: Factura electrónica
B14: Cotización | E14: Moneda | F14: PEN
B16: PROYECTO | E16: EJECUCIÓN DEL SERVICIO
B17: Proyecto | C17: INFINITY 224 | E17: Lugar | F17: Remoto y showroom Infinity 224
B18: Centro de costo | C18: Marketing y ventas | E18: Dirección | F18: Calle La Apacheta 224, San Miguel, Lima
B19: Partida | C19: Gestión de redes sociales | E19: Contacto | F19: Martín Montezuma · 987 208 622
B20: Requerimiento | E20: Horario / plazo | F20: Del 1 al 31 de agosto de 2026
A22: # | B22: Código | C22: Descripción | D22: Und. | E22: Cantidad | F22: P. unitario | G22: Parcial
A23: 1 | C23: Asesoría en estrategia de marketing y administración de redes sociales, del 1 al 31 de agosto de 2026 | D23: mes | E23: 1 | F23: 4500 | G23: =IF(OR(E23="",F23=""),"",ROUND(E23*F23,2)) -> 4500
A24: 2 | G24: =IF(OR(E24="",F24=""),"",ROUND(E24*F24,2))
A25: 3 | G25: =IF(OR(E25="",F25=""),"",ROUND(E25*F25,2))
A26: 4 | G26: =IF(OR(E26="",F26=""),"",ROUND(E26*F26,2))
A27: 5 | G27: =IF(OR(E27="",F27=""),"",ROUND(E27*F27,2))
A28: 6 | G28: =IF(OR(E28="",F28=""),"",ROUND(E28*F28,2))
A29: 7 | G29: =IF(OR(E29="",F29=""),"",ROUND(E29*F29,2))
A30: 8 | G30: =IF(OR(E30="",F30=""),"",ROUND(E30*F30,2))
A31: 9 | G31: =IF(OR(E31="",F31=""),"",ROUND(E31*F31,2))
A32: 10 | G32: =IF(OR(E32="",F32=""),"",ROUND(E32*F32,2))
A33: 11 | G33: =IF(OR(E33="",F33=""),"",ROUND(E33*F33,2))
A34: 12 | G34: =IF(OR(E34="",F34=""),"",ROUND(E34*F34,2))
B36: CONDICIONES
B37: Forma de pago | C37: Mensual, a 7 días de la conformidad y factura | E37: Subtotal | G37: =ROUND(SUM(G23:G34),2) -> 4500
B38: Plazo | C38: Servicio mensual | E38: IGV 18 % | G38: =IF(F13="Factura electrónica",ROUND(G37*0.18,2),0) -> 810
B39: Garantía | E39: Otros cargos | G39: 0
B40: Penalidad | C40: Descuento proporcional por entregables no cumplidos | E40: Total | G40: =ROUND(G37+G38+G39,2) -> 5310
B41: Abonar en | C41: =IF(IFERROR(INDEX(Proveedores!$A$5:$K$65,MATCH($C$10,Proveedores!$A$5:$A$65,0),10)&"","")="","Cuenta del proveedor por registrar en Proveedores",TRIM(IFERROR(INDEX(Proveedores!$A$5:$K$65,MATCH($C$10,Proveedores!$A$5:$A$65,0),8)&"","")&" "&IFERROR(INDEX(Proveedores!$A$5:$K$65,MATCH($C$10,Proveedores!$A$5:$A$65,0),9)&"","")&" · "&IFERROR(INDEX(Proveedores!$A$5:$K$65,MATCH($C$10,Proveedores!$A$5:$A$65,0),10)&"","")&IF(IFERROR(INDEX(Proveedores!$A$5:$K$65,MATCH($C$10,Proveedores!$A$5:$A$65,0),11)&"","")="",""," · CCI "&IFERROR(INDEX(Proveedores!$A$5:$K$65,MATCH($C$10,Proveedores!$A$5:$A$65,0),11)&"","")))) -> BCP Soles · 1932525695069 | E41: Detracción % | F41: 0.12 | G41: =IF(F41="",0,ROUND(G40*F41,0)) -> 637
E42: Retención 4.ª cat. | G42: =IF(AND(F13="Recibo por honorarios",G37>1500),ROUND(G37*0.08,2),0) -> 0
E43: Neto a pagar | G43: =G40-G41-G42 -> 4673
B44: OBSERVACIONES | E44: =IF($F$14="USD","Montos en dólares americanos","Montos en soles") -> Montos en soles
...

Sheet OC MZA
E1: ORDEN DE COMPRA
E2: Empresa | F2: Código | G2: MZA
E3: Correlativo | G3: 28
E4: Fecha | G4: 44209
A5: =INDEX(Empresas!$A$2:$G$4,MATCH($G$2,Empresas!$A$2:$A$4,0),2) -> MONTEZUMA ARQUITECTOS GERENCIA Y CONSTRUCCIÓN E.I.R.L. | E5: N.º | F5: ="OC-"&$G$2&"-"&IF($G$4="","AAAA",YEAR($G$4))&"-"&TEXT($G$3,"0000") -> OC-MZA-2021-0028
A6: ="RUC "&INDEX(Empresas!$A$2:$G$4,MATCH($G$2,Empresas!$A$2:$A$4,0),3)&" · "&INDEX(Empresas!$A$2:$G$4,MATCH($G$2,Empresas!$A$2:$A$4,0),4) -> RUC 20602354785 · Calle Puquina 138, Maranga, San Miguel, Lima | E6: Revisión | G6: 0
A7: =INDEX(Empresas!$A$2:$G$4,MATCH($G$2,Empresas!$A$2:$A$4,0),5)&" · "&INDEX(Empresas!$A$2:$G$4,MATCH($G$2,Empresas!$A$2:$A$4,0),6)&" · "&INDEX(Empresas!$A$2:$G$4,MATCH($G$2,Empresas!$A$2:$A$4,0),7) -> Cel. 940 207 936 · info@montezumaarquitectos.com · www.montezumaarquitectos.com
B9: PROVEEDOR | E9: FACTURAR A
B10: Proveedor | C10: SMS CONSULTING AND TRAINING SAC | E10: Razón social | F10: =INDEX(Empresas!$A$2:$G$4,MATCH($G$2,Empresas!$A$2:$A$4,0),2) -> MONTEZUMA ARQUITECTOS GERENCIA Y CONSTRUCCIÓN E.I.R.L.
B11: RUC / DNI | C11: =IFERROR(INDEX(Proveedores!$A$5:$K$65,MATCH($C$10,Proveedores!$A$5:$A$65,0),2)&"","") | E11: RUC | F11: =INDEX(Empresas!$A$2:$G$4,MATCH($G$2,Empresas!$A$2:$A$4,0),3) -> 20602354785
B12: Dirección | C12: =IFERROR(INDEX(Proveedores!$A$5:$K$65,MATCH($C$10,Proveedores!$A$5:$A$65,0),4)&"","") | E12: Dir. fiscal | F12: =INDEX(Empresas!$A$2:$G$4,MATCH($G$2,Empresas!$A$2:$A$4,0),4) -> Calle Puquina 138, Maranga, San Miguel, Lima
B13: Contacto | C13: =TRIM(IFERROR(INDEX(Proveedores!$A$5:$K$65,MATCH($C$10,Proveedores!$A$5:$A$65,0),5)&"","")&" "&IFERROR(INDEX(Proveedores!$A$5:$K$65,MATCH($C$10,Proveedores!$A$5:$A$65,0),6)&"","")) | E13: Comprobante | F13: Factura electrónica
B14: Cotización | C14: 04 - 2021 | E14: Moneda | F14: PEN
B16: PROYECTO | E16: ENTREGA
B17: Proyecto | C17: PRISMA · ETAPA 1 | E17: Lugar | F17: Obra Prisma, etapa 1
B18: Centro de costo | C18: Obra | E18: Dirección | F18: Av. Fundo Chacra Cerro, lote 62, Comas, Lima
B19: Partida | C19: Concreto premezclado | E19: Contacto | F19: Ing. Miguel Iñapi · 946 198 130
B20: Requerimiento | E20: Horario / plazo | F20: L-V 8:30–12:00 y 14:00–16:00 · S 8:30–12:00
A22: # | B22: Código | C22: Descripción | D22: Und. | E22: Cantidad | F22: P. unitario | G22: Parcial
A23: 1 | C23: Concreto premezclado tipo HS, f′c 175, piedra 67 o 57, slump 5 a 6 pulg, IP | D23: m³ | E23: 6 | F23: 213 | G23: =IF(OR(E23="",F23=""),"",ROUND(E23*F23,2)) -> 1278
A24: 2 | C24: Servicio de bomba (mínimo 20 m³) | D24: glb | E24: 1 | F24: 600 | G24: =IF(OR(E24="",F24=""),"",ROUND(E24*F24,2)) -> 600
A25: 3 | G25: =IF(OR(E25="",F25=""),"",ROUND(E25*F25,2))
A26: 4 | G26: =IF(OR(E26="",F26=""),"",ROUND(E26*F26,2))
A27: 5 | G27: =IF(OR(E27="",F27=""),"",ROUND(E27*F27,2))
A28: 6 | G28: =IF(OR(E28="",F28=""),"",ROUND(E28*F28,2))
A29: 7 | G29: =IF(OR(E29="",F29=""),"",ROUND(E29*F29,2))
A30: 8 | G30: =IF(OR(E30="",F30=""),"",ROUND(E30*F30,2))
A31: 9 | G31: =IF(OR(E31="",F31=""),"",ROUND(E31*F31,2))
A32: 10 | G32: =IF(OR(E32="",F32=""),"",ROUND(E32*F32,2))
A33: 11 | G33: =IF(OR(E33="",F33=""),"",ROUND(E33*F33,2))
A34: 12 | G34: =IF(OR(E34="",F34=""),"",ROUND(E34*F34,2))
B36: CONDICIONES
B37: Forma de pago | C37: Contado o según línea de crédito | E37: Subtotal | G37: =ROUND(SUM(G23:G34),2) -> 1878
B38: Plazo | C38: Vaciado programado con 48 h de aviso | E38: IGV 18 % | G38: =IF(F13="Factura electrónica",ROUND(G37*0.18,2),0) -> 338.04
B39: Garantía | C39: Certificado de calidad y probetas | E39: Otros cargos | G39: 0
B40: Penalidad | E40: Total | G40: =ROUND(G37+G38+G39,2) -> 2216.04
B41: Abonar en | C41: =IF(IFERROR(INDEX(Proveedores!$A$5:$K$65,MATCH($C$10,Proveedores!$A$5:$A$65,0),10)&"","")="","Cuenta del proveedor por registrar en Proveedores",TRIM(IFERROR(INDEX(Proveedores!$A$5:$K$65,MATCH($C$10,Proveedores!$A$5:$A$65,0),8)&"","")&" "&IFERROR(INDEX(Proveedores!$A$5:$K$65,MATCH($C$10,Proveedores!$A$5:$A$65,0),9)&"","")&" · "&IFERROR(INDEX(Proveedores!$A$5:$K$65,MATCH($C$10,Proveedores!$A$5:$A$65,0),10)&"","")&IF(IFERROR(INDEX(Proveedores!$A$5:$K$65,MATCH($C$10,Proveedores!$A$5:$A$65,0),11)&"","")="",""," · CCI "&IFERROR(INDEX(Proveedores!$A$5:$K$65,MATCH($C$10,Proveedores!$A$5:$A$65,0),11)&"","")))) -> Cuenta del proveedor por registrar en Proveedores | E41: Detracción % | G41: =IF(F41="",0,ROUND(G40*F41,0)) -> 0
E42: Retención 4.ª cat. | G42: =IF(AND(F13="Recibo por honorarios",G37>1500),ROUND(G37*0.08,2),0) -> 0
E43: Neto a pagar | G43: =G40-G41-G42 -> 2216.04
B44: OBSERVACIONES | E44: =IF($F$14="USD","Montos en dólares americanos","Montos en soles") -> Montos en soles
...

Sheet OS MZA
E1: ORDEN DE SERVICIO
E2: Empresa | F2: Código | G2: MZA
E3: Correlativo | G3: 1
E4: Fecha
A5: =INDEX(Empresas!$A$2:$G$4,MATCH($G$2,Empresas!$A$2:$A$4,0),2) -> MONTEZUMA ARQUITECTOS GERENCIA Y CONSTRUCCIÓN E.I.R.L. | E5: N.º | F5: ="OS-"&$G$2&"-"&IF($G$4="","AAAA",YEAR($G$4))&"-"&TEXT($G$3,"0000") -> OS-MZA-AAAA-0001
A6: ="RUC "&INDEX(Empresas!$A$2:$G$4,MATCH($G$2,Empresas!$A$2:$A$4,0),3)&" · "&INDEX(Empresas!$A$2:$G$4,MATCH($G$2,Empresas!$A$2:$A$4,0),4) -> RUC 20602354785 · Calle Puquina 138, Maranga, San Miguel, Lima | E6: Revisión | G6: 0
A7: =INDEX(Empresas!$A$2:$G$4,MATCH($G$2,Empresas!$A$2:$A$4,0),5)&" · "&INDEX(Empresas!$A$2:$G$4,MATCH($G$2,Empresas!$A$2:$A$4,0),6)&" · "&INDEX(Empresas!$A$2:$G$4,MATCH($G$2,Empresas!$A$2:$A$4,0),7) -> Cel. 940 207 936 · info@montezumaarquitectos.com · www.montezumaarquitectos.com
B9: PROVEEDOR | E9: FACTURAR A
B10: Proveedor | E10: Razón social | F10: =INDEX(Empresas!$A$2:$G$4,MATCH($G$2,Empresas!$A$2:$A$4,0),2) -> MONTEZUMA ARQUITECTOS GERENCIA Y CONSTRUCCIÓN E.I.R.L.
B11: RUC / DNI | C11: =IFERROR(INDEX(Proveedores!$A$5:$K$65,MATCH($C$10,Proveedores!$A$5:$A$65,0),2)&"","") | E11: RUC | F11: =INDEX(Empresas!$A$2:$G$4,MATCH($G$2,Empresas!$A$2:$A$4,0),3) -> 20602354785
B12: Dirección | C12: =IFERROR(INDEX(Proveedores!$A$5:$K$65,MATCH($C$10,Proveedores!$A$5:$A$65,0),4)&"","") | E12: Dir. fiscal | F12: =INDEX(Empresas!$A$2:$G$4,MATCH($G$2,Empresas!$A$2:$A$4,0),4) -> Calle Puquina 138, Maranga, San Miguel, Lima
B13: Contacto | C13: =TRIM(IFERROR(INDEX(Proveedores!$A$5:$K$65,MATCH($C$10,Proveedores!$A$5:$A$65,0),5)&"","")&" "&IFERROR(INDEX(Proveedores!$A$5:$K$65,MATCH($C$10,Proveedores!$A$5:$A$65,0),6)&"","")) | E13: Comprobante | F13: Factura electrónica
B14: Cotización | E14: Moneda | F14: PEN
B16: PROYECTO | E16: EJECUCIÓN DEL SERVICIO
B17: Proyecto | E17: Lugar
B18: Centro de costo | E18: Dirección
B19: Partida | E19: Contacto
B20: Requerimiento | E20: Horario / plazo
A22: # | B22: Código | C22: Descripción | D22: Und. | E22: Cantidad | F22: P. unitario | G22: Parcial
A23: 1 | G23: =IF(OR(E23="",F23=""),"",ROUND(E23*F23,2))
A24: 2 | G24: =IF(OR(E24="",F24=""),"",ROUND(E24*F24,2))
A25: 3 | G25: =IF(OR(E25="",F25=""),"",ROUND(E25*F25,2))
A26: 4 | G26: =IF(OR(E26="",F26=""),"",ROUND(E26*F26,2))
A27: 5 | G27: =IF(OR(E27="",F27=""),"",ROUND(E27*F27,2))
A28: 6 | G28: =IF(OR(E28="",F28=""),"",ROUND(E28*F28,2))
A29: 7 | G29: =IF(OR(E29="",F29=""),"",ROUND(E29*F29,2))
A30: 8 | G30: =IF(OR(E30="",F30=""),"",ROUND(E30*F30,2))
A31: 9 | G31: =IF(OR(E31="",F31=""),"",ROUND(E31*F31,2))
A32: 10 | G32: =IF(OR(E32="",F32=""),"",ROUND(E32*F32,2))
A33: 11 | G33: =IF(OR(E33="",F33=""),"",ROUND(E33*F33,2))
A34: 12 | G34: =IF(OR(E34="",F34=""),"",ROUND(E34*F34,2))
B36: CONDICIONES
B37: Forma de pago | E37: Subtotal | G37: =ROUND(SUM(G23:G34),2) -> 0
B38: Plazo | E38: IGV 18 % | G38: =IF(F13="Factura electrónica",ROUND(G37*0.18,2),0) -> 0
B39: Garantía | E39: Otros cargos | G39: 0
B40: Penalidad | E40: Total | G40: =ROUND(G37+G38+G39,2) -> 0
B41: Abonar en | C41: =IF(IFERROR(INDEX(Proveedores!$A$5:$K$65,MATCH($C$10,Proveedores!$A$5:$A$65,0),10)&"","")="","Cuenta del proveedor por registrar en Proveedores",TRIM(IFERROR(INDEX(Proveedores!$A$5:$K$65,MATCH($C$10,Proveedores!$A$5:$A$65,0),8)&"","")&" "&IFERROR(INDEX(Proveedores!$A$5:$K$65,MATCH($C$10,Proveedores!$A$5:$A$65,0),9)&"","")&" · "&IFERROR(INDEX(Proveedores!$A$5:$K$65,MATCH($C$10,Proveedores!$A$5:$A$65,0),10)&"","")&IF(IFERROR(INDEX(Proveedores!$A$5:$K$65,MATCH($C$10,Proveedores!$A$5:$A$65,0),11)&"","")="",""," · CCI "&IFERROR(INDEX(Proveedores!$A$5:$K$65,MATCH($C$10,Proveedores!$A$5:$A$65,0),11)&"","")))) -> Cuenta del proveedor por registrar en Proveedores | E41: Detracción % | G41: =IF(F41="",0,ROUND(G40*F41,0)) -> 0
E42: Retención 4.ª cat. | G42: =IF(AND(F13="Recibo por honorarios",G37>1500),ROUND(G37*0.08,2),0) -> 0
E43: Neto a pagar | G43: =G40-G41-G42 -> 0
B44: OBSERVACIONES | E44: =IF($F$14="USD","Montos en dólares americanos","Montos en soles") -> Montos en soles
...
